Workbook

Sheet Leverage Model
E1: Round of 32 | I1: Sweet 16 | M1: Elite 8 | Q1: Final 4 | U1: Finals | Y1: Champion
A2: Team | B2: Seed | C2: Region | D2: KenPom % | E2: Yahoo Pick % | F2: Leverage | G2: Effective Leverage | H2: KenPom % | I2: Yahoo Pick % | J2: Leverage | K2: Effective Leverage | L2: KenPom % | M2: Yahoo Pick % | N2: Leverage | O2: Effective Leverage | P2: KenPom % | Q2: Yahoo Pick % | R2: Leverage | S2: Effective Leverage | T2: KenPom % | U2: Yahoo Pick % | V2: Leverage | W2: Effective Leverage | X2: KenPom % | Y2: Yahoo Pick % | Z2: Leverage | AA2: Effective Leverage
A3: Duke | B3: 1 | C3: East | D3: =VLOOKUP(A3,KenPom!1:1000,4,FALSE) -> 99.1 | E3: =VLOOKUP(A3,Yahoo!1:1000,4,FALSE) -> 98.21 | F3: =D3-E3 -> 0.89 | G3: =Round(F3*(D3/100),2) -> 0.88 | H3: =VLOOKUP(A3,KenPom!1:1000,5,FALSE) -> 85.3 | I3: =VLOOKUP(A3,Yahoo!1:1000,5,FALSE) -> 93.59 | J3: =H3-I3 -> -8.29 | K3: =round(J3*(H3/100),2) -> -7.07 | L3: =VLOOKUP(A3,KenPom!1:1000,6,FALSE) -> 69 | M3: =VLOOKUP(A3,Yahoo!1:1000,6,FALSE) -> 78.77 | N3: =L3-M3 -> -9.77 | O3: =round(N3*(L3/100),2) -> -6.74 | P3: =VLOOKUP(A3,KenPom!1:1000,7,FALSE) -> 52.7 | Q3: =VLOOKUP(A3,Yahoo!1:1000,7,FALSE) -> 64.67 | R3: =P3-Q3 -> -11.97 | S3: =round(R3*(P3/100),2) -> -6.31 | T3: =VLOOKUP(A3,KenPom!1:1000,8,FALSE) -> 33.3 | U3: =VLOOKUP(A3,Yahoo!1:1000,8,FALSE) -> 49.51 | V3: =T3-U3 -> -16.21 | W3: =round(V3*(T3/100),2) -> -5.4 | X3: =VLOOKUP(A3,KenPom!1:1000,9,FALSE) -> 21 | Y3: =VLOOKUP(A3,Yahoo!1:1000,9,FALSE) -> 30.24 | Z3: =X3-Y3 -> -9.24 | AA3: =round(Z3*(X3/100),2) -> -1.94
A4: Arizona | B4: 1 | C4: West | D4: =VLOOKUP(A4,KenPom!2:1001,4,FALSE) -> 99.6 | E4: =VLOOKUP(A4,Yahoo!2:1001,4,FALSE) -> 94.82 | F4: =D4-E4 -> 4.78 | G4: =Round(F4*(D4/100),2) -> 4.76 | H4: =VLOOKUP(A4,KenPom!2:1001,5,FALSE) -> 85.7 | I4: =VLOOKUP(A4,Yahoo!2:1001,5,FALSE) -> 89.38 | J4: =H4-I4 -> -3.68 | K4: =round(J4*(H4/100),2) -> -3.15 | L4: =VLOOKUP(A4,KenPom!2:1001,6,FALSE) -> 68.8 | M4: =VLOOKUP(A4,Yahoo!2:1001,6,FALSE) -> 74.48 | N4: =L4-M4 -> -5.68 | O4: =round(N4*(L4/100),2) -> -3.91 | P4: =VLOOKUP(A4,KenPom!2:1001,7,FALSE) -> 49.7 | Q4: =VLOOKUP(A4,Yahoo!2:1001,7,FALSE) -> 56.08 | R4: =P4-Q4 -> -6.38 | S4: =round(R4*(P4/100),2) -> -3.17 | T4: =VLOOKUP(A4,KenPom!2:1001,8,FALSE) -> 32.1 | U4: =VLOOKUP(A4,Yahoo!2:1001,8,FALSE) -> 38.93 | V4: =T4-U4 -> -6.83 | W4: =round(V4*(T4/100),2) -> -2.19 | X4: =VLOOKUP(A4,KenPom!2:1001,9,FALSE) -> 18.5 | Y4: =VLOOKUP(A4,Yahoo!2:1001,9,FALSE) -> 19.37 | Z4: =X4-Y4 -> -0.87 | AA4: =round(Z4*(X4/100),2) -> -0.16
A5: Michigan | B5: 1 | C5: Midwest | D5: =VLOOKUP(A5,KenPom!3:1002,4,FALSE) -> 99.5 | E5: =VLOOKUP(A5,Yahoo!3:1002,4,FALSE) -> 94.22 | F5: =D5-E5 -> 5.28 | G5: =Round(F5*(D5/100),2) -> 5.25 | H5: =VLOOKUP(A5,KenPom!3:1002,5,FALSE) -> 88.2 | I5: =VLOOKUP(A5,Yahoo!3:1002,5,FALSE) -> 89.6 | J5: =H5-I5 -> -1.4 | K5: =round(J5*(H5/100),2) -> -1.23 | L5: =VLOOKUP(A5,KenPom!3:1002,6,FALSE) -> 70.9 | M5: =VLOOKUP(A5,Yahoo!3:1002,6,FALSE) -> 77.11 | N5: =L5-M5 -> -6.21 | O5: =round(N5*(L5/100),2) -> -4.4 | P5: =VLOOKUP(A5,KenPom!3:1002,7,FALSE) -> 50.2 | Q5: =VLOOKUP(A5,Yahoo!3:1002,7,FALSE) -> 58.91 | R5: =P5-Q5 -> -8.71 | S5: =round(R5*(P5/100),2) -> -4.37 | T5: =VLOOKUP(A5,KenPom!3:1002,8,FALSE) -> 30.4 | U5: =VLOOKUP(A5,Yahoo!3:1002,8,FALSE) -> 28.46 | V5: =T5-U5 -> 1.94 | W5: =round(V5*(T5/100),2) -> 0.59 | X5: =VLOOKUP(A5,KenPom!3:1002,9,FALSE) -> 18.4 | Y5: =VLOOKUP(A5,Yahoo!3:1002,9,FALSE) -> 14.48 | Z5: =X5-Y5 -> 3.92 | AA5: =round(Z5*(X5/100),2) -> 0.72
A6: Florida | B6: 1 | C6: South | D6: =VLOOKUP(A6,KenPom!4:1003,4,FALSE) -> 99.8 | E6: =VLOOKUP(A6,Yahoo!4:1003,4,FALSE) -> 95.36 | F6: =D6-E6 -> 4.44 | G6: =Round(F6*(D6/100),2) -> 4.43 | H6: =VLOOKUP(A6,KenPom!4:1003,5,FALSE) -> 77.9 | I6: =VLOOKUP(A6,Yahoo!4:1003,5,FALSE) -> 88.13 | J6: =H6-I6 -> -10.23 | K6: =round(J6*(H6/100),2) -> -7.97 | L6: =VLOOKUP(A6,KenPom!4:1003,6,FALSE) -> 53.2 | M6: =VLOOKUP(A6,Yahoo!4:1003,6,FALSE) -> 74.68 | N6: =L6-M6 -> -21.48 | O6: =round(N6*(L6/100),2) -> -11.43 | P6: =VLOOKUP(A6,KenPom!4:1003,7,FALSE) -> 30.1 | Q6: =VLOOKUP(A6,Yahoo!4:1003,7,FALSE) -> 41.77 | R6: =P6-Q6 -> -11.67 | S6: =round(R6*(P6/100),2) -> -3.51 | T6: =VLOOKUP(A6,KenPom!4:1003,8,FALSE) -> 15.8 | U6: =VLOOKUP(A6,Yahoo!4:1003,8,FALSE) -> 13.68 | V6: =T6-U6 -> 2.12 | W6: =round(V6*(T6/100),2) -> 0.33 | X6: =VLOOKUP(A6,KenPom!4:1003,9,FALSE) -> 7.5 | Y6: =VLOOKUP(A6,Yahoo!4:1003,9,FALSE) -> 6.48 | Z6: =X6-Y6 -> 1.02 | AA6: =round(Z6*(X6/100),2) -> 0.08
A7: Uconn | B7: 2 | C7: East | D7: =VLOOKUP(A7,KenPom!5:1004,4,FALSE) -> 95.9 | E7: =VLOOKUP(A7,Yahoo!5:1004,4,FALSE) -> 96.15 | F7: =D7-E7 -> -0.25 | G7: =Round(F7*(D7/100),2) -> -0.24 | H7: =VLOOKUP(A7,KenPom!5:1004,5,FALSE) -> 66.1 | I7: =VLOOKUP(A7,Yahoo!5:1004,5,FALSE) -> 77.4 | J7: =H7-I7 -> -11.3 | K7: =round(J7*(H7/100),2) -> -7.47 | L7: =VLOOKUP(A7,KenPom!5:1004,6,FALSE) -> 35.5 | M7: =VLOOKUP(A7,Yahoo!5:1004,6,FALSE) -> 48.29 | N7: =L7-M7 -> -12.79 | O7: =round(N7*(L7/100),2) -> -4.54 | P7: =VLOOKUP(A7,KenPom!5:1004,7,FALSE) -> 13.1 | Q7: =VLOOKUP(A7,Yahoo!5:1004,7,FALSE) -> 13.25 | R7: =P7-Q7 -> -0.15 | S7: =round(R7*(P7/100),2) -> -0.02 | T7: =VLOOKUP(A7,KenPom!5:1004,8,FALSE) -> 4.9 | U7: =VLOOKUP(A7,Yahoo!5:1004,8,FALSE) -> 7.19 | V7: =T7-U7 -> -2.29 | W7: =round(V7*(T7/100),2) -> -0.11 | X7: =VLOOKUP(A7,KenPom!5:1004,9,FALSE) -> 1.9 | Y7: =VLOOKUP(A7,Yahoo!5:1004,9,FALSE) -> 3.61 | Z7: =X7-Y7 -> -1.71 | AA7: =round(Z7*(X7/100),2) -> -0.03
A8: Purdue | B8: 2 | C8: West | D8: =VLOOKUP(A8,KenPom!6:1005,4,FALSE) -> 97.6 | E8: =VLOOKUP(A8,Yahoo!6:1005,4,FALSE) -> 93.62 | F8: =D8-E8 -> 3.98 | G8: =Round(F8*(D8/100),2) -> 3.88 | H8: =VLOOKUP(A8,KenPom!6:1005,5,FALSE) -> 74.9 | I8: =VLOOKUP(A8,Yahoo!6:1005,5,FALSE) -> 76.5 | J8: =H8-I8 -> -1.6 | K8: =round(J8*(H8/100),2) -> -1.2 | L8: =VLOOKUP(A8,KenPom!6:1005,6,FALSE) -> 46.7 | M8: =VLOOKUP(A8,Yahoo!6:1005,6,FALSE) -> 47.5 | N8: =L8-M8 -> -0.8 | O8: =round(N8*(L8/100),2) -> -0.37 | P8: =VLOOKUP(A8,KenPom!6:1005,7,FALSE) -> 20.8 | Q8: =VLOOKUP(A8,Yahoo!6:1005,7,FALSE) -> 15.85 | R8: =P8-Q8 -> 4.95 | S8: =round(R8*(P8/100),2) -> 1.03 | T8: =VLOOKUP(A8,KenPom!6:1005,8,FALSE) -> 10.3 | U8: =VLOOKUP(A8,Yahoo!6:1005,8,FALSE) -> 7.47 | V8: =T8-U8 -> 2.83 | W8: =round(V8*(T8/100),2) -> 0.29 | X8: =VLOOKUP(A8,KenPom!6:1005,9,FALSE) -> 4.3 | Y8: =VLOOKUP(A8,Yahoo!6:1005,9,FALSE) -> 3.17 | Z8: =X8-Y8 -> 1.13 | AA8: =round(Z8*(X8/100),2) -> 0.05
A9: Iowa State | B9: 2 | C9: Midwest | D9: =VLOOKUP(A9,KenPom!7:1006,4,FALSE) -> 98.4 | E9: =VLOOKUP(A9,Yahoo!7:1006,4,FALSE) -> 91.25 | F9: =D9-E9 -> 7.15 | G9: =Round(F9*(D9/100),2) -> 7.04 | H9: =VLOOKUP(A9,KenPom!7:1006,5,FALSE) -> 75.3 | I9: =VLOOKUP(A9,Yahoo!7:1006,5,FALSE) -> 69.43 | J9: =H9-I9 -> 5.87 | K9: =round(J9*(H9/100),2) -> 4.42 | L9: =VLOOKUP(A9,KenPom!7:1006,6,FALSE) -> 49.4 | M9: =VLOOKUP(A9,Yahoo!7:1006,6,FALSE) -> 47.35 | N9: =L9-M9 -> 2.05 | O9: =round(N9*(L9/100),2) -> 1.01 | P9: =VLOOKUP(A9,KenPom!7:1006,7,FALSE) -> 22.9 | Q9: =VLOOKUP(A9,Yahoo!7:1006,7,FALSE) -> 16.41 | R9: =P9-Q9 -> 6.49 | S9: =round(R9*(P9/100),2) -> 1.49 | T9: =VLOOKUP(A9,KenPom!7:1006,8,FALSE) -> 11.2 | U9: =VLOOKUP(A9,Yahoo!7:1006,8,FALSE) -> 5.12 | V9: =T9-U9 -> 6.08 | W9: =round(V9*(T9/100),2) -> 0.68 | X9: =VLOOKUP(A9,KenPom!7:1006,9,FALSE) -> 5.4 | Y9: =VLOOKUP(A9,Yahoo!7:1006,9,FALSE) -> 1.82 | Z9: =X9-Y9 -> 3.58 | AA9: =round(Z9*(X9/100),2) -> 0.19
A10: Houston | B10: 2 | C10: South | D10: =VLOOKUP(A10,KenPom!8:1007,4,FALSE) -> 96.9 | E10: =VLOOKUP(A10,Yahoo!8:1007,4,FALSE) -> 93.67 | F10: =D10-E10 -> 3.23 | G10: =Round(F10*(D10/100),2) -> 3.13 | H10: =VLOOKUP(A10,KenPom!8:1007,5,FALSE) -> 73.5 | I10: =VLOOKUP(A10,Yahoo!8:1007,5,FALSE) -> 81.46 | J10: =H10-I10 -> -7.96 | K10: =round(J10*(H10/100),2) -> -5.85 | L10: =VLOOKUP(A10,KenPom!8:1007,6,FALSE) -> 43.6 | M10: =VLOOKUP(A10,Yahoo!8:1007,6,FALSE) -> 58.94 | N10: =L10-M10 -> -15.34 | O10: =round(N10*(L10/100),2) -> -6.69 | P10: =VLOOKUP(A10,KenPom!8:1007,7,FALSE) -> 25.1 | Q10: =VLOOKUP(A10,Yahoo!8:1007,7,FALSE) -> 34 | R10: =P10-Q10 -> -8.9 | S10: =round(R10*(P10/100),2) -> -2.23 | T10: =VLOOKUP(A10,KenPom!8:1007,8,FALSE) -> 12.9 | U10: =VLOOKUP(A10,Yahoo!8:1007,8,FALSE) -> 12.62 | V10: =T10-U10 -> 0.28 | W10: =round(V10*(T10/100),2) -> 0.04 | X10: =VLOOKUP(A10,KenPom!8:1007,9,FALSE) -> 6.1 | Y10: =VLOOKUP(A10,Yahoo!8:1007,9,FALSE) -> 5.2 | Z10: =X10-Y10 -> 0.9 | AA10: =round(Z10*(X10/100),2) -> 0.05
A11: Michigan State | B11: 3 | C11: East | D11: =VLOOKUP(A11,KenPom!9:1008,4,FALSE) -> 91.6 | E11: =VLOOKUP(A11,Yahoo!9:1008,4,FALSE) -> 94.58 | F11: =D11-E11 -> -2.98 | G11: =Round(F11*(D11/100),2) -> -2.73 | H11: =VLOOKUP(A11,KenPom!9:1008,5,FALSE) -> 57.5 | I11: =VLOOKUP(A11,Yahoo!9:1008,5,FALSE) -> 73.1 | J11: =H11-I11 -> -15.6 | K11: =round(J11*(H11/100),2) -> -8.97 | L11: =VLOOKUP(A11,KenPom!9:1008,6,FALSE) -> 32.9 | M11: =VLOOKUP(A11,Yahoo!9:1008,6,FALSE) -> 34.57 | N11: =L11-M11 -> -1.67 | O11: =round(N11*(L11/100),2) -> -0.55 | P11: =VLOOKUP(A11,KenPom!9:1008,7,FALSE) -> 12 | Q11: =VLOOKUP(A11,Yahoo!9:1008,7,FALSE) -> 7.72 | R11: =P11-Q11 -> 4.28 | S11: =round(R11*(P11/100),2) -> 0.51 | T11: =VLOOKUP(A11,KenPom!9:1008,8,FALSE) -> 4.6 | U11: =VLOOKUP(A11,Yahoo!9:1008,8,FALSE) -> 3.36 | V11: =T11-U11 -> 1.24 | W11: =round(V11*(T11/100),2) -> 0.06 | X11: =VLOOKUP(A11,KenPom!9:1008,9,FALSE) -> 1.8 | Y11: =VLOOKUP(A11,Yahoo!9:1008,9,FALSE) -> 1.36 | Z11: =X11-Y11 -> 0.44 | AA11: =round(Z11*(X11/100),2) -> 0.01
A12: Gonzaga | B12: 3 | C12: West | D12: =VLOOKUP(A12,KenPom!10:1009,4,FALSE) -> 96.3 | E12: =VLOOKUP(A12,Yahoo!10:1009,4,FALSE) -> 91.65 | F12: =D12-E12 -> 4.65 | G12: =Round(F12*(D12/100),2) -> 4.48 | H12: =VLOOKUP(A12,KenPom!10:1009,5,FALSE) -> 63.4 | I12: =VLOOKUP(A12,Yahoo!10:1009,5,FALSE) -> 64.19 | J12: =H12-I12 -> -0.79 | K12: =round(J12*(H12/100),2) -> -0.5 | L12: =VLOOKUP(A12,KenPom!10:1009,6,FALSE) -> 31.6 | M12: =VLOOKUP(A12,Yahoo!10:1009,6,FALSE) -> 30.43 | N12: =L12-M12 -> 1.17 | O12: =round(N12*(L12/100),2) -> 0.37 | P12: =VLOOKUP(A12,KenPom!10:1009,7,FALSE) -> 11.7 | Q12: =VLOOKUP(A12,Yahoo!10:1009,7,FALSE) -> 10.08 | R12: =P12-Q12 -> 1.62 | S12: =round(R12*(P12/100),2) -> 0.19 | T12: =VLOOKUP(A12,KenPom!10:1009,8,FALSE) -> 4.9 | U12: =VLOOKUP(A12,Yahoo!10:1009,8,FALSE) -> 4.9 | V12: =T12-U12 -> 0 | W12: =round(V12*(T12/100),2) -> 0 | X12: =VLOOKUP(A12,KenPom!10:1009,9,FALSE) -> 1.7 | Y12: =VLOOKUP(A12,Yahoo!10:1009,9,FALSE) -> 1.91 | Z12: =X12-Y12 -> -0.21 | AA12: =round(Z12*(X12/100),2) -> 0
A13: Virginia | B13: 3 | C13: Midwest | D13: =VLOOKUP(A13,KenPom!11:1010,4,FALSE) -> 93.1 | E13: =VLOOKUP(A13,Yahoo!11:1010,4,FALSE) -> 90.14 | F13: =D13-E13 -> 2.96 | G13: =Round(F13*(D13/100),2) -> 2.76 | H13: =VLOOKUP(A13,KenPom!11:1010,5,FALSE) -> 53.1 | I13: =VLOOKUP(A13,Yahoo!11:1010,5,FALSE) -> 59.96 | J13: =H13-I13 -> -6.86 | K13: =round(J13*(H13/100),2) -> -3.64 | L13: =VLOOKUP(A13,KenPom!11:1010,6,FALSE) -> 23.2 | M13: =VLOOKUP(A13,Yahoo!11:1010,6,FALSE) -> 25.79 | N13: =L13-M13 -> -2.59 | O13: =round(N13*(L13/100),2) -> -0.6 | P13: =VLOOKUP(A13,KenPom!11:1010,7,FALSE) -> 7.8 | Q13: =VLOOKUP(A13,Yahoo!11:1010,7,FALSE) -> 7.57 | R13: =P13-Q13 -> 0.23 | S13: =round(R13*(P13/100),2) -> 0.02 | T13: =VLOOKUP(A13,KenPom!11:1010,8,FALSE) -> 2.7 | U13: =VLOOKUP(A13,Yahoo!11:1010,8,FALSE) -> 2.39 | V13: =T13-U13 -> 0.31 | W13: =round(V13*(T13/100),2) -> 0.01 | X13: =VLOOKUP(A13,KenPom!11:1010,9,FALSE) -> 1 | Y13: =VLOOKUP(A13,Yahoo!11:1010,9,FALSE) -> 0.77 | Z13: =X13-Y13 -> 0.23 | AA13: =round(Z13*(X13/100),2) -> 0
A14: Illinois | B14: 3 | C14: South | D14: =VLOOKUP(A14,KenPom!12:1011,4,FALSE) -> 97 | E14: =VLOOKUP(A14,Yahoo!12:1011,4,FALSE) -> 90.7 | F14: =D14-E14 -> 6.3 | G14: =Round(F14*(D14/100),2) -> 6.11 | H14: =VLOOKUP(A14,KenPom!12:1011,5,FALSE) -> 75.5 | I14: =VLOOKUP(A14,Yahoo!12:1011,5,FALSE) -> 60.96 | J14: =H14-I14 -> 14.54 | K14: =round(J14*(H14/100),2) -> 10.98 | L14: =VLOOKUP(A14,KenPom!12:1011,6,FALSE) -> 40.8 | M14: =VLOOKUP(A14,Yahoo!12:1011,6,FALSE) -> 20.39 | N14: =L14-M14 -> 20.41 | O14: =round(N14*(L14/100),2) -> 8.33 | P14: =VLOOKUP(A14,KenPom!12:1011,7,FALSE) -> 22.3 | Q14: =VLOOKUP(A14,Yahoo!12:1011,7,FALSE) -> 9.17 | R14: =P14-Q14 -> 13.13 | S14: =round(R14*(P14/100),2) -> 2.93 | T14: =VLOOKUP(A14,KenPom!12:1011,8,FALSE) -> 10.7 | U14: =VLOOKUP(A14,Yahoo!12:1011,8,FALSE) -> 3.05 | V14: =T14-U14 -> 7.65 | W14: =round(V14*(T14/100),2) -> 0.82 | X14: =VLOOKUP(A14,KenPom!12:1011,9,FALSE) -> 4.6 | Y14: =VLOOKUP(A14,Yahoo!12:1011,9,FALSE) -> 1.14 | Z14: =X14-Y14 -> 3.46 | AA14: =round(Z14*(X14/100),2) -> 0.16
A15: Kansas | B15: 4 | C15: East | D15: =VLOOKUP(A15,KenPom!13:1012,4,FALSE) -> 86.6 | E15: =VLOOKUP(A15,Yahoo!13:1012,4,FALSE) -> 94.16 | F15: =D15-E15 -> -7.56 | G15: =Round(F15*(D15/100),2) -> -6.55 | H15: =VLOOKUP(A15,KenPom!13:1012,5,FALSE) -> 45.5 | I15: =VLOOKUP(A15,Yahoo!13:1012,5,FALSE) -> 43.8 | J15: =H15-I15 -> 1.7 | K15: =round(J15*(H15/100),2) -> 0.77 | L15: =VLOOKUP(A15,KenPom!13:1012,6,FALSE) -> 11.4 | M15: =VLOOKUP(A15,Yahoo!13:1012,6,FALSE) -> 7.93 | N15: =L15-M15 -> 3.47 | O15: =round(N15*(L15/100),2) -> 0.4 | P15: =VLOOKUP(A15,KenPom!13:1012,7,FALSE) -> 5.2 | Q15: =VLOOKUP(A15,Yahoo!13:1012,7,FALSE) -> 4.29 | R15: =P15-Q15 -> 0.91 | S15: =round(R15*(P15/100),2) -> 0.05 | T15: =VLOOKUP(A15,KenPom!13:1012,8,FALSE) -> 1.6 | U15: =VLOOKUP(A15,Yahoo!13:1012,8,FALSE) -> 2.49 | V15: =T15-U15 -> -0.89 | W15: =round(V15*(T15/100),2) -> -0.01 | X15: =VLOOKUP(A15,KenPom!13:1012,9,FALSE) -> 0.5 | Y15: =VLOOKUP(A15,Yahoo!13:1012,9,FALSE) -> 1.56 | Z15: =X15-Y15 -> -1.06 | AA15: =round(Z15*(X15/100),2) -> -0.01
A16: Arkansas | B16: 4 | C16: West | D16: =VLOOKUP(A16,KenPom!14:1013,4,FALSE) -> 90.7 | E16: =VLOOKUP(A16,Yahoo!14:1013,4,FALSE) -> 88.69 | F16: =D16-E16 -> 2.01 | G16: =Round(F16*(D16/100),2) -> 1.82 | H16: =VLOOKUP(A16,KenPom!14:1013,5,FALSE) -> 56.2 | I16: =VLOOKUP(A16,Yahoo!14:1013,5,FALSE) -> 53.07 | J16: =H16-I16 -> 3.13 | K16: =round(J16*(H16/100),2) -> 1.76 | L16: =VLOOKUP(A16,KenPom!14:1013,6,FALSE) -> 15.9 | M16: =VLOOKUP(A16,Yahoo!14:1013,6,FALSE) -> 10.86 | N16: =L16-M16 -> 5.04 | O16: =round(N16*(L16/100),2) -> 0.8 | P16: =VLOOKUP(A16,KenPom!14:1013,7,FALSE) -> 7.2 | Q16: =VLOOKUP(A16,Yahoo!14:1013,7,FALSE) -> 6.48 | R16: =P16-Q16 -> 0.72 | S16: =round(R16*(P16/100),2) -> 0.05 | T16: =VLOOKUP(A16,KenPom!14:1013,8,FALSE) -> 2.7 | U16: =VLOOKUP(A16,Yahoo!14:1013,8,FALSE) -> 2.95 | V16: =T16-U16 -> -0.25 | W16: =round(V16*(T16/100),2) -> -0.01 | X16: =VLOOKUP(A16,KenPom!14:1013,9,FALSE) -> 0.8 | Y16: =VLOOKUP(A16,Yahoo!14:1013,9,FALSE) -> 1.21 | Z16: =X16-Y16 -> -0.41 | AA16: =round(Z16*(X16/100),2) -> 0
A17: Alabama | B17: 4 | C17: Midwest | D17: =VLOOKUP(A17,KenPom!15:1014,4,FALSE) -> 79.6 | E17: =VLOOKUP(A17,Yahoo!15:1014,4,FALSE) -> 87.86 | F17: =D17-E17 -> -8.26 | G17: =Round(F17*(D17/100),2) -> -6.57 | H17: =VLOOKUP(A17,KenPom!15:1014,5,FALSE) -> 46.5 | I17: =VLOOKUP(A17,Yahoo!15:1014,5,FALSE) -> 54.95 | J17: =H17-I17 -> -8.45 | K17: =round(J17*(H17/100),2) -> -3.93 | L17: =VLOOKUP(A17,KenPom!15:1014,6,FALSE) -> 12.7 | M17: =VLOOKUP(A17,Yahoo!15:1014,6,FALSE) -> 10.89 | N17: =L17-M17 -> 1.81 | O17: =round(N17*(L17/100),2) -> 0.23 | P17: =VLOOKUP(A17,KenPom!15:1014,7,FALSE) -> 6.1 | Q17: =VLOOKUP(A17,Yahoo!15:1014,7,FALSE) -> 4.86 | R17: =P17-Q17 -> 1.24 | S17: =round(R17*(P17/100),2) -> 0.08 | T17: =VLOOKUP(A17,KenPom!15:1014,8,FALSE) -> 2.1 | U17: =VLOOKUP(A17,Yahoo!15:1014,8,FALSE) -> 1.52 | V17: =T17-U17 -> 0.58 | W17: =round(V17*(T17/100),2) -> 0.01 | X17: =VLOOKUP(A17,KenPom!15:1014,9,FALSE) -> 0.7 | Y17: =VLOOKUP(A17,Yahoo!15:1014,9,FALSE) -> 0.56 | Z17: =X17-Y17 -> 0.14 | AA17: =round(Z17*(X17/100),2) -> 0
A18: Nebraska | B18: 4 | C18: South | D18: =VLOOKUP(A18,KenPom!16:1015,4,FALSE) -> 92.7 | E18: =VLOOKUP(A18,Yahoo!16:1015,4,FALSE) -> 84.73 | F18: =D18-E18 -> 7.97 | G18: =Round(F18*(D18/100),2) -> 7.39 | H18: =VLOOKUP(A18,KenPom!16:1015,5,FALSE) -> 48.7 | I18: =VLOOKUP(A18,Yahoo!16:1015,5,FALSE) -> 36.52 | J18: =H18-I18 -> 12.18 | K18: =round(J18*(H18/100),2) -> 5.93 | L18: =VLOOKUP(A18,KenPom!16:1015,6,FALSE) -> 18.6 | M18: =VLOOKUP(A18,Yahoo!16:1015,6,FALSE) -> 6.31 | N18: =L18-M18 -> 12.29 | O18: =round(N18*(L18/100),2) -> 2.29 | P18: =VLOOKUP(A18,KenPom!16:1015,7,FALSE) -> 7.2 | Q18: =VLOOKUP(A18,Yahoo!16:1015,7,FALSE) -> 1.92 | R18: =P18-Q18 -> 5.28 | S18: =round(R18*(P18/100),2) -> 0.38 | T18: =VLOOKUP(A18,KenPom!16:1015,8,FALSE) -> 2.5 | U18: =VLOOKUP(A18,Yahoo!16:1015,8,FALSE) -> 0.62 | V18: =T18-U18 -> 1.88 | W18: =round(V18*(T18/100),2) -> 0.05 | X18: =VLOOKUP(A18,KenPom!16:1015,9,FALSE) -> 0.8 | Y18: =VLOOKUP(A18,Yahoo!16:1015,9,FALSE) -> 0.29 | Z18: =X18-Y18 -> 0.51 | AA18: =round(Z18*(X18/100),2) -> 0
A19: St John's | B19: 5 | C19: East | D19: =VLOOKUP(A19,KenPom!17:1016,4,FALSE) -> 79.6 | E19: =VLOOKUP(A19,Yahoo!17:1016,4,FALSE) -> 87.6 | F19: =D19-E19 -> -8 | G19: =Round(F19*(D19/100),2) -> -6.37 | H19: =VLOOKUP(A19,KenPom!17:1016,5,FALSE) -> 46.5 | I19: =VLOOKUP(A19,Yahoo!17:1016,5,FALSE) -> 51.62 | J19: =H19-I19 -> -5.12 | K19: =round(J19*(H19/100),2) -> -2.38 | L19: =VLOOKUP(A19,KenPom!17:1016,6,FALSE) -> 12.7 | M19: =VLOOKUP(A19,Yahoo!17:1016,6,FALSE) -> 9.06 | N19: =L19-M19 -> 3.64 | O19: =round(N19*(L19/100),2) -> 0.46 | P19: =VLOOKUP(A19,KenPom!17:1016,7,FALSE) -> 6.1 | Q19: =VLOOKUP(A19,Yahoo!17:1016,7,FALSE) -> 5.2 | R19: =P19-Q19 -> 0.9 | S19: =round(R19*(P19/100),2) -> 0.05 | T19: =VLOOKUP(A19,KenPom!17:1016,8,FALSE) -> 2.1 | U19: =VLOOKUP(A19,Yahoo!17:1016,8,FALSE) -> 2.41 | V19: =T19-U19 -> -0.31 | W19: =round(V19*(T19/100),2) -> -0.01 | X19: =VLOOKUP(A19,KenPom!17:1016,9,FALSE) -> 0.7 | Y19: =VLOOKUP(A19,Yahoo!17:1016,9,FALSE) -> 1.15 | Z19: =X19-Y19 -> -0.45 | AA19: =round(Z19*(X19/100),2) -> 0
A20: Wisconsin | B20: 5 | C20: West | D20: =VLOOKUP(A20,KenPom!18:1017,4,FALSE) -> 83.3 | E20: =VLOOKUP(A20,Yahoo!18:1017,4,FALSE) -> 80.7 | F20: =D20-E20 -> 2.6 | G20: =Round(F20*(D20/100),2) -> 2.17 | H20: =VLOOKUP(A20,KenPom!18:1017,5,FALSE) -> 39.3 | I20: =VLOOKUP(A20,Yahoo!18:1017,5,FALSE) -> 38.02 | J20: =H20-I20 -> 1.28 | K20: =round(J20*(H20/100),2) -> 0.5 | L20: =VLOOKUP(A20,KenPom!18:1017,6,FALSE) -> 9.2 | M20: =VLOOKUP(A20,Yahoo!18:1017,6,FALSE) -> 6.87 | N20: =L20-M20 -> 2.33 | O20: =round(N20*(L20/100),2) -> 0.21 | P20: =VLOOKUP(A20,KenPom!18:1017,7,FALSE) -> 3.6 | Q20: =VLOOKUP(A20,Yahoo!18:1017,7,FALSE) -> 3.02 | R20: =P20-Q20 -> 0.58 | S20: =round(R20*(P20/100),2) -> 0.02 | T20: =VLOOKUP(A20,KenPom!18:1017,8,FALSE) -> 1.2 | U20: =VLOOKUP(A20,Yahoo!18:1017,8,FALSE) -> 1.52 | V20: =T20-U20 -> -0.32 | W20: =round(V20*(T20/100),2) -> 0 | X20: =VLOOKUP(A20,KenPom!18:1017,9,FALSE) -> 0.3 | Y20: =VLOOKUP(A20,Yahoo!18:1017,9,FALSE) -> 0.9 | Z20: =X20-Y20 -> -0.6 | AA20: =round(Z20*(X20/100),2) -> 0
A21: Texas Tech | B21: 5 | C21: Midwest | D21: =VLOOKUP(A21,KenPom!19:1018,4,FALSE) -> 78.2 | E21: =VLOOKUP(A21,Yahoo!19:1018,4,FALSE) -> 73.24 | F21: =D21-E21 -> 4.96 | G21: =Round(F21*(D21/100),2) -> 3.88 | H21: =VLOOKUP(A21,KenPom!19:1018,5,FALSE) -> 42 | I21: =VLOOKUP(A21,Yahoo!19:1018,5,FALSE) -> 33.74 | J21: =H21-I21 -> 8.26 | K21: =round(J21*(H21/100),2) -> 3.47 | L21: =VLOOKUP(A21,KenPom!19:1018,6,FALSE) -> 11.2 | M21: =VLOOKUP(A21,Yahoo!19:1018,6,FALSE) -> 4.91 | N21: =L21-M21 -> 6.29 | O21: =round(N21*(L21/100),2) -> 0.7 | P21: =VLOOKUP(A21,KenPom!19:1018,7,FALSE) -> 4.7 | Q21: =VLOOKUP(A21,Yahoo!19:1018,7,FALSE) -> 1.84 | R21: =P21-Q21 -> 2.86 | S21: =round(R21*(P21/100),2) -> 0.13 | T21: =VLOOKUP(A21,KenPom!19:1018,8,FALSE) -> 1.6 | U21: =VLOOKUP(A21,Yahoo!19:1018,8,FALSE) -> 0.59 | V21: =T21-U21 -> 1.01 | W21: =round(V21*(T21/100),2) -> 0.02 | X21: =VLOOKUP(A21,KenPom!19:1018,9,FALSE) -> 0.5 | Y21: =VLOOKUP(A21,Yahoo!19:1018,9,FALSE) -> 0.21 | Z21: =X21-Y21 -> 0.29 | AA21: =round(Z21*(X21/100),2) -> 0
A22: Vanderbilt | B22: 5 | C22: South | D22: =VLOOKUP(A22,KenPom!20:1019,4,FALSE) -> 82.3 | E22: =VLOOKUP(A22,Yahoo!20:1019,4,FALSE) -> 80.87 | F22: =D22-E22 -> 1.43 | G22: =Round(F22*(D22/100),2) -> 1.18 | H22: =VLOOKUP(A22,KenPom!20:1019,5,FALSE) -> 46.3 | I22: =VLOOKUP(A22,Yahoo!20:1019,5,FALSE) -> 53.24 | J22: =H22-I22 -> -6.94 | K22: =round(J22*(H22/100),2) -> -3.21 | L22: =VLOOKUP(A22,KenPom!20:1019,6,FALSE) -> 19 | M22: =VLOOKUP(A22,Yahoo!20:1019,6,FALSE) -> 10.57 | N22: =L22-M22 -> 8.43 | O22: =round(N22*(L22/100),2) -> 1.6 | P22: =VLOOKUP(A22,KenPom!20:1019,7,FALSE) -> 8 | Q22: =VLOOKUP(A22,Yahoo!20:1019,7,FALSE) -> 2.87 | R22: =P22-Q22 -> 5.13 | S22: =round(R22*(P22/100),2) -> 0.41 | T22: =VLOOKUP(A22,KenPom!20:1019,8,FALSE) -> 3 | U22: =VLOOKUP(A22,Yahoo!20:1019,8,FALSE) -> 0.73 | V22: =T22-U22 -> 2.27 | W22: =round(V22*(T22/100),2) -> 0.07 | X22: =VLOOKUP(A22,KenPom!20:1019,9,FALSE) -> 1 | Y22: =VLOOKUP(A22,Yahoo!20:1019,9,FALSE) -> 0.26 | Z22: =X22-Y22 -> 0.74 | AA22: =round(Z22*(X22/100),2) -> 0.01
A23: Louisville | B23: 6 | C23: East | D23: =VLOOKUP(A23,KenPom!21:1020,4,FALSE) -> 72.3 | E23: =VLOOKUP(A23,Yahoo!21:1020,4,FALSE) -> 64.54 | F23: =D23-E23 -> 7.76 | G23: =Round(F23*(D23/100),2) -> 5.61 | H23: =VLOOKUP(A23,KenPom!21:1020,5,FALSE) -> 33.9 | I23: =VLOOKUP(A23,Yahoo!21:1020,5,FALSE) -> 18.24 | J23: =H23-I23 -> 15.66 | K23: =round(J23*(H23/100),2) -> 5.31 | L23: =VLOOKUP(A23,KenPom!21:1020,6,FALSE) -> 17.2 | M23: =VLOOKUP(A23,Yahoo!21:1020,6,FALSE) -> 7.24 | N23: =L23-M23 -> 9.96 | O23: =round(N23*(L23/100),2) -> 1.71 | P23: =VLOOKUP(A23,KenPom!21:1020,7,FALSE) -> 5.3 | Q23: =VLOOKUP(A23,Yahoo!21:1020,7,FALSE) -> 0.68 | R23: =P23-Q23 -> 4.62 | S23: =round(R23*(P23/100),2) -> 0.24 | T23: =VLOOKUP(A23,KenPom!21:1020,8,FALSE) -> 1.7 | U23: =VLOOKUP(A23,Yahoo!21:1020,8,FALSE) -> 0.25 | V23: =T23-U23 -> 1.45 | W23: =round(V23*(T23/100),2) -> 0.02 | X23: =VLOOKUP(A23,KenPom!21:1020,9,FALSE) -> 0.5 | Y23: =VLOOKUP(A23,Yahoo!21:1020,9,FALSE) -> 0.11 | Z23: =X23-Y23 -> 0.39 | AA23: =round(Z23*(X23/100),2) -> 0
A24: BYU | B24: 6 | C24: West | D24: =VLOOKUP(A24,KenPom!22:1021,4,FALSE) -> 60 | E24: =VLOOKUP(A24,Yahoo!22:1021,4,FALSE) -> 78.9 | F24: =D24-E24 -> -18.9 | G24: =Round(F24*(D24/100),2) -> -11.34 | H24: =VLOOKUP(A24,KenPom!22:1021,5,FALSE) -> 23.8 | I24: =VLOOKUP(A24,Yahoo!22:1021,5,FALSE) -> 27.54 | J24: =H24-I24 -> -3.74 | K24: =round(J24*(H24/100),2) -> -0.89 | L24: =VLOOKUP(A24,KenPom!22:1021,6,FALSE) -> 9.3 | M24: =VLOOKUP(A24,Yahoo!22:1021,6,FALSE) -> 11.44 | N24: =L24-M24 -> -2.14 | O24: =round(N24*(L24/100),2) -> -0.2 | P24: =VLOOKUP(A24,KenPom!22:1021,7,FALSE) -> 2.5 | Q24: =VLOOKUP(A24,Yahoo!22:1021,7,FALSE) -> 1.71 | R24: =P24-Q24 -> 0.79 | S24: =round(R24*(P24/100),2) -> 0.02 | T24: =VLOOKUP(A24,KenPom!22:1021,8,FALSE) -> 0.8 | U24: =VLOOKUP(A24,Yahoo!22:1021,8,FALSE) -> 0.79 | V24: =T24-U24 -> 0.01 | W24: =round(V24*(T24/100),2) -> 0 | X24: =VLOOKUP(A24,KenPom!22:1021,9,FALSE) -> 0.2 | Y24: =VLOOKUP(A24,Yahoo!22:1021,9,FALSE) -> 0.31 | Z24: =X24-Y24 -> -0.11 | AA24: =round(Z24*(X24/100),2) -> 0
A25: Tenneessee | B25: 6 | C25: Midwest | D25: =VLOOKUP(A25,KenPom!23:1022,4,FALSE) -> 73.1 | E25: =VLOOKUP(A25,Yahoo!23:1022,4,FALSE) -> 82.59 | F25: =D25-E25 -> -9.49 | G25: =Round(F25*(D25/100),2) -> -6.94 | H25: =VLOOKUP(A25,KenPom!23:1022,5,FALSE) -> 37.6 | I25: =VLOOKUP(A25,Yahoo!23:1022,5,FALSE) -> 31.55 | J25: =H25-I25 -> 6.05 | K25: =round(J25*(H25/100),2) -> 2.27 | L25: =VLOOKUP(A25,KenPom!23:1022,6,FALSE) -> 15.8 | M25: =VLOOKUP(A25,Yahoo!23:1022,6,FALSE) -> 11.99 | N25: =L25-M25 -> 3.81 | O25: =round(N25*(L25/100),2) -> 0.6 | P25: =VLOOKUP(A25,KenPom!23:1022,7,FALSE) -> 5.1 | Q25: =VLOOKUP(A25,Yahoo!23:1022,7,FALSE) -> 1.8 | R25: =P25-Q25 -> 3.3 | S25: =round(R25*(P25/100),2) -> 0.17 | T25: =VLOOKUP(A25,KenPom!23:1022,8,FALSE) -> 1.8 | U25: =VLOOKUP(A25,Yahoo!23:1022,8,FALSE) -> 0.61 | V25: =T25-U25 -> 1.19 | W25: =round(V25*(T25/100),2) -> 0.02 | X25: =VLOOKUP(A25,KenPom!23:1022,9,FALSE) -> 0.6 | Y25: =VLOOKUP(A25,Yahoo!23:1022,9,FALSE) -> 0.24 | Z25: =X25-Y25 -> 0.36 | AA25: =round(Z25*(X25/100),2) -> 0
A26: North Carolina | B26: 6 | C26: South | D26: =VLOOKUP(A26,KenPom!24:1023,4,FALSE) -> 58.9 | E26: =VLOOKUP(A26,Yahoo!24:1023,4,FALSE) -> 69.27 | F26: =D26-E26 -> -10.37 | G26: =Round(F26*(D26/100),2) -> -6.11 | H26: =VLOOKUP(A26,KenPom!24:1023,5,FALSE) -> 15.7 | I26: =VLOOKUP(A26,Yahoo!24:1023,5,FALSE) -> 29.2 | J26: =H26-I26 -> -13.5 | K26: =round(J26*(H26/100),2) -> -2.12 | L26: =VLOOKUP(A26,KenPom!24:1023,6,FALSE) -> 4.7 | M26: =VLOOKUP(A26,Yahoo!24:1023,6,FALSE) -> 12.72 | N26: =L26-M26 -> -8.02 | O26: =round(N26*(L26/100),2) -> -0.38 | P26: =VLOOKUP(A26,KenPom!24:1023,7,FALSE) -> 1.4 | Q26: =VLOOKUP(A26,Yahoo!24:1023,7,FALSE) -> 4.3 | R26: =P26-Q26 -> -2.9 | S26: =round(R26*(P26/100),2) -> -0.04 | T26: =VLOOKUP(A26,KenPom!24:1023,8,FALSE) -> 0.4 | U26: =VLOOKUP(A26,Yahoo!24:1023,8,FALSE) -> 1.04 | V26: =T26-U26 -> -0.64 | W26: =round(V26*(T26/100),2) -> 0 | X26: =VLOOKUP(A26,KenPom!24:1023,9,FALSE) -> 0.07 | Y26: =VLOOKUP(A26,Yahoo!24:1023,9,FALSE) -> 0.51 | Z26: =X26-Y26 -> -0.44 | AA26: =round(Z26*(X26/100),2) -> 0
A27: UCLA | B27: 7 | C27: East | D27: =VLOOKUP(A27,KenPom!25:1024,4,FALSE) -> 65.8 | E27: =VLOOKUP(A27,Yahoo!25:1024,4,FALSE) -> 67.25 | F27: =D27-E27 -> -1.45 | G27: =Round(F27*(D27/100),2) -> -0.95 | H27: =VLOOKUP(A27,KenPom!25:1024,5,FALSE) -> 25.1 | I27: =VLOOKUP(A27,Yahoo!25:1024,5,FALSE) -> 17.41 | J27: =H27-I27 -> 7.69 | K27: =round(J27*(H27/100),2) -> 1.93 | L27: =VLOOKUP(A27,KenPom!25:1024,6,FALSE) -> 10 | M27: =VLOOKUP(A27,Yahoo!25:1024,6,FALSE) -> 6.09 | N27: =L27-M27 -> 3.91 | O27: =round(N27*(L27/100),2) -> 0.39 | P27: =VLOOKUP(A27,KenPom!25:1024,7,FALSE) -> 2.5 | Q27: =VLOOKUP(A27,Yahoo!25:1024,7,FALSE) -> 0.95 | R27: =P27-Q27 -> 1.55 | S27: =round(R27*(P27/100),2) -> 0.04 | T27: =VLOOKUP(A27,KenPom!25:1024,8,FALSE) -> 0.7 | U27: =VLOOKUP(A27,Yahoo!25:1024,8,FALSE) -> 0.47 | V27: =T27-U27 -> 0.23 | W27: =round(V27*(T27/100),2) -> 0 | X27: =VLOOKUP(A27,KenPom!25:1024,9,FALSE) -> 0.2 | Y27: =VLOOKUP(A27,Yahoo!25:1024,9,FALSE) -> 0.26 | Z27: =X27-Y27 -> -0.06 | AA27: =round(Z27*(X27/100),2) -> 0
A28: Miami | B28: 7 | C28: West | D28: =VLOOKUP(A28,KenPom!26:1025,4,FALSE) -> 62.7 | E28: =VLOOKUP(A28,Yahoo!26:1025,4,FALSE) -> 60.84 | F28: =D28-E28 -> 1.86 | G28: =Round(F28*(D28/100),2) -> 1.17 | H28: =VLOOKUP(A28,KenPom!26:1025,5,FALSE) -> 17.5 | I28: =VLOOKUP(A28,Yahoo!26:1025,5,FALSE) -> 14.81 | J28: =H28-I28 -> 2.69 | K28: =round(J28*(H28/100),2) -> 0.47 | L28: =VLOOKUP(A28,KenPom!26:1025,6,FALSE) -> 6.6 | M28: =VLOOKUP(A28,Yahoo!26:1025,6,FALSE) -> 4.75 | N28: =L28-M28 -> 1.85 | O28: =round(N28*(L28/100),2) -> 0.12 | P28: =VLOOKUP(A28,KenPom!26:1025,7,FALSE) -> 1.6 | Q28: =VLOOKUP(A28,Yahoo!26:1025,7,FALSE) -> 1.36 | R28: =P28-Q28 -> 0.24 | S28: =round(R28*(P28/100),2) -> 0 | T28: =VLOOKUP(A28,KenPom!26:1025,8,FALSE) -> 0.4 | U28: =VLOOKUP(A28,Yahoo!26:1025,8,FALSE) -> 0.48 | V28: =T28-U28 -> -0.08 | W28: =round(V28*(T28/100),2) -> 0 | X28: =VLOOKUP(A28,KenPom!26:1025,9,FALSE) -> 0.08 | Y28: =VLOOKUP(A28,Yahoo!26:1025,9,FALSE) -> 0.21 | Z28: =X28-Y28 -> -0.13 | AA28: =round(Z28*(X28/100),2) -> 0
A29: Kentucky | B29: 7 | C29: Midwest | D29: =VLOOKUP(A29,KenPom!27:1026,4,FALSE) -> 55.5 | E29: =VLOOKUP(A29,Yahoo!27:1026,4,FALSE) -> 65.63 | F29: =D29-E29 -> -10.13 | G29: =Round(F29*(D29/100),2) -> -5.62 | H29: =VLOOKUP(A29,KenPom!27:1026,5,FALSE) -> 14.6 | I29: =VLOOKUP(A29,Yahoo!27:1026,5,FALSE) -> 20.83 | J29: =H29-I29 -> -6.23 | K29: =round(J29*(H29/100),2) -> -0.91 | L29: =VLOOKUP(A29,KenPom!27:1026,6,FALSE) -> 6 | M29: =VLOOKUP(A29,Yahoo!27:1026,6,FALSE) -> 8.35 | N29: =L29-M29 -> -2.35 | O29: =round(N29*(L29/100),2) -> -0.14 | P29: =VLOOKUP(A29,KenPom!27:1026,7,FALSE) -> 1.3 | Q29: =VLOOKUP(A29,Yahoo!27:1026,7,FALSE) -> 2.98 | R29: =P29-Q29 -> -1.68 | S29: =round(R29*(P29/100),2) -> -0.02 | T29: =VLOOKUP(A29,KenPom!27:1026,8,FALSE) -> 0.3 | U29: =VLOOKUP(A29,Yahoo!27:1026,8,FALSE) -> 1.62 | V29: =T29-U29 -> -1.32 | W29: =round(V29*(T29/100),2) -> 0 | X29: =VLOOKUP(A29,KenPom!27:1026,9,FALSE) -> 0.08 | Y29: =VLOOKUP(A29,Yahoo!27:1026,9,FALSE) -> 0.38 | Z29: =X29-Y29 -> -0.3 | AA29: =round(Z29*(X29/100),2) -> 0
A30: Saint Mary's | B30: 7 | C30: South | D30: =VLOOKUP(A30,KenPom!28:1027,4,FALSE) -> 60.4 | E30: =VLOOKUP(A30,Yahoo!28:1027,4,FALSE) -> 50.99 | F30: =D30-E30 -> 9.41 | G30: =Round(F30*(D30/100),2) -> 5.68 | H30: =VLOOKUP(A30,KenPom!28:1027,5,FALSE) -> 17.9 | I30: =VLOOKUP(A30,Yahoo!28:1027,5,FALSE) -> 8.48 | J30: =H30-I30 -> 9.42 | K30: =round(J30*(H30/100),2) -> 1.69 | L30: =VLOOKUP(A30,KenPom!28:1027,6,FALSE) -> 6.6 | M30: =VLOOKUP(A30,Yahoo!28:1027,6,FALSE) -> 1.88 | N30: =L30-M30 -> 4.72 | O30: =round(N30*(L30/100),2) -> 0.31 | P30: =VLOOKUP(A30,KenPom!28:1027,7,FALSE) -> 2.2 | Q30: =VLOOKUP(A30,Yahoo!28:1027,7,FALSE) -> 0.6 | R30: =P30-Q30 -> 1.6 | S30: =round(R30*(P30/100),2) -> 0.04 | T30: =VLOOKUP(A30,KenPom!28:1027,8,FALSE) -> 0.7 | U30: =VLOOKUP(A30,Yahoo!28:1027,8,FALSE) -> 0.16 | V30: =T30-U30 -> 0.54 | W30: =round(V30*(T30/100),2) -> 0 | X30: =VLOOKUP(A30,KenPom!28:1027,9,FALSE) -> 0.2 | Y30: =VLOOKUP(A30,Yahoo!28:1027,9,FALSE) -> 0.06 | Z30: =X30-Y30 -> 0.14 | AA30: =round(Z30*(X30/100),2) -> 0
A31: Ohio State | B31: 8 | C31: East | D31: =VLOOKUP(A31,KenPom!29:1028,4,FALSE) -> 61 | E31: =VLOOKUP(A31,Yahoo!29:1028,4,FALSE) -> 59.53 | F31: =D31-E31 -> 1.47 | G31: =Round(F31*(D31/100),2) -> 0.9 | H31: =VLOOKUP(A31,KenPom!29:1028,5,FALSE) -> 10.3 | I31: =VLOOKUP(A31,Yahoo!29:1028,5,FALSE) -> 3.21 | J31: =H31-I31 -> 7.09 | K31: =round(J31*(H31/100),2) -> 0.73 | L31: =VLOOKUP(A31,KenPom!29:1028,6,FALSE) -> 4.7 | M31: =VLOOKUP(A31,Yahoo!29:1028,6,FALSE) -> 1.72 | N31: =L31-M31 -> 2.98 | O31: =round(N31*(L31/100),2) -> 0.14 | P31: =VLOOKUP(A31,KenPom!29:1028,7,FALSE) -> 1.9 | Q31: =VLOOKUP(A31,Yahoo!29:1028,7,FALSE) -> 1.03 | R31: =P31-Q31 -> 0.87 | S31: =round(R31*(P31/100),2) -> 0.02 | T31: =VLOOKUP(A31,KenPom!29:1028,8,FALSE) -> 0.5 | U31: =VLOOKUP(A31,Yahoo!29:1028,8,FALSE) -> 0.34 | V31: =T31-U31 -> 0.16 | W31: =round(V31*(T31/100),2) -> 0 | X31: =VLOOKUP(A31,KenPom!29:1028,9,FALSE) -> 0.1 | Y31: =VLOOKUP(A31,Yahoo!29:1028,9,FALSE) -> 0.2 | Z31: =X31-Y31 -> -0.1 | AA31: =round(Z31*(X31/100),2) -> 0
A32: Villanova | B32: 8 | C32: West | D32: =VLOOKUP(A32,KenPom!30:1029,4,FALSE) -> 47.7 | E32: =VLOOKUP(A32,Yahoo!30:1029,4,FALSE) -> 54.46 | F32: =D32-E32 -> -6.76 | G32: =Round(F32*(D32/100),2) -> -3.22 | H32: =VLOOKUP(A32,KenPom!30:1029,5,FALSE) -> 6.8 | I32: =VLOOKUP(A32,Yahoo!30:1029,5,FALSE) -> 4.78 | J32: =H32-I32 -> 2.02 | K32: =round(J32*(H32/100),2) -> 0.14 | L32: =VLOOKUP(A32,KenPom!30:1029,6,FALSE) -> 2.7 | M32: =VLOOKUP(A32,Yahoo!30:1029,6,FALSE) -> 2.56 | N32: =L32-M32 -> 0.14 | O32: =round(N32*(L32/100),2) -> 0 | P32: =VLOOKUP(A32,KenPom!30:1029,7,FALSE) -> 0.8 | Q32: =VLOOKUP(A32,Yahoo!30:1029,7,FALSE) -> 0.83 | R32: =P32-Q32 -> -0.03 | S32: =round(R32*(P32/100),2) -> 0 | T32: =VLOOKUP(A32,KenPom!30:1029,8,FALSE) -> 0.2 | U32: =VLOOKUP(A32,Yahoo!30:1029,8,FALSE) -> 0.4 | V32: =T32-U32 -> -0.2 | W32: =round(V32*(T32/100),2) -> 0 | X32: =VLOOKUP(A32,KenPom!30:1029,9,FALSE) -> 0.05 | Y32: =VLOOKUP(A32,Yahoo!30:1029,9,FALSE) -> 0.16 | Z32: =X32-Y32 -> -0.11 | AA32: =round(Z32*(X32/100),2) -> 0
A33: Georgia | B33: 8 | C33: Midwest | D33: =VLOOKUP(A33,KenPom!31:1030,4,FALSE) -> 56 | E33: =VLOOKUP(A33,Yahoo!31:1030,4,FALSE) -> 53.77 | F33: =D33-E33 -> 2.23 | G33: =Round(F33*(D33/100),2) -> 1.25 | H33: =VLOOKUP(A33,KenPom!31:1030,5,FALSE) -> 7.2 | I33: =VLOOKUP(A33,Yahoo!31:1030,5,FALSE) -> 3.57 | J33: =H33-I33 -> 3.63 | K33: =round(J33*(H33/100),2) -> 0.26 | L33: =VLOOKUP(A33,KenPom!31:1030,6,FALSE) -> 2.9 | M33: =VLOOKUP(A33,Yahoo!31:1030,6,FALSE) -> 1.24 | N33: =L33-M33 -> 1.66 | O33: =round(N33*(L33/100),2) -> 0.05 | P33: =VLOOKUP(A33,KenPom!31:1030,7,FALSE) -> 0.9 | Q33: =VLOOKUP(A33,Yahoo!31:1030,7,FALSE) -> 0.55 | R33: =P33-Q33 -> 0.35 | S33: =round(R33*(P33/100),2) -> 0 | T33: =VLOOKUP(A33,KenPom!31:1030,8,FALSE) -> 0.2 | U33: =VLOOKUP(A33,Yahoo!31:1030,8,FALSE) -> 0.24 | V33: =T33-U33 -> -0.04 | W33: =round(V33*(T33/100),2) -> 0 | X33: =VLOOKUP(A33,KenPom!31:1030,9,FALSE) -> 0.03 | Y33: =VLOOKUP(A33,Yahoo!31:1030,9,FALSE) -> 0.12 | Z33: =X33-Y33 -> -0.09 | AA33: =round(Z33*(X33/100),2) -> 0
A34: Clemson | B34: 8 | C34: South | D34: =VLOOKUP(A34,KenPom!32:1031,4,FALSE) -> 43 | E34: =VLOOKUP(A34,Yahoo!32:1031,4,FALSE) -> 46.69 | F34: =D34-E34 -> -3.69 | G34: =Round(F34*(D34/100),2) -> -1.59 | H34: =VLOOKUP(A34,KenPom!32:1031,5,FALSE) -> 8.1 | I34: =VLOOKUP(A34,Yahoo!32:1031,5,FALSE) -> 3.35 | J34: =H34-I34 -> 4.75 | K34: =round(J34*(H34/100),2) -> 0.38 | L34: =VLOOKUP(A34,KenPom!32:1031,6,FALSE) -> 2.8 | M34: =VLOOKUP(A34,Yahoo!32:1031,6,FALSE) -> 1.58 | N34: =L34-M34 -> 1.22 | O34: =round(N34*(L34/100),2) -> 0.03 | P34: =VLOOKUP(A34,KenPom!32:1031,7,FALSE) -> 0.7 | Q34: =VLOOKUP(A34,Yahoo!32:1031,7,FALSE) -> 0.57 | R34: =P34-Q34 -> 0.13 | S34: =round(R34*(P34/100),2) -> 0 | T34: =VLOOKUP(A34,KenPom!32:1031,8,FALSE) -> 0.2 | U34: =VLOOKUP(A34,Yahoo!32:1031,8,FALSE) -> 0.19 | V34: =T34-U34 -> 0.01 | W34: =round(V34*(T34/100),2) -> 0 | X34: =VLOOKUP(A34,KenPom!32:1031,9,FALSE) -> 0.03 | Y34: =VLOOKUP(A34,Yahoo!32:1031,9,FALSE) -> 0.09 | Z34: =X34-Y34 -> -0.06 | AA34: =round(Z34*(X34/100),2) -> 0
A35: TCU | B35: 9 | C35: East | D35: =VLOOKUP(A35,KenPom!33:1032,4,FALSE) -> 39 | E35: =VLOOKUP(A35,Yahoo!33:1032,4,FALSE) -> 38.35 | F35: =D35-E35 -> 0.65 | G35: =Round(F35*(D35/100),2) -> 0.25 | H35: =VLOOKUP(A35,KenPom!33:1032,5,FALSE) -> 4.3 | I35: =VLOOKUP(A35,Yahoo!33:1032,5,FALSE) -> 1.59 | J35: =H35-I35 -> 2.71 | K35: =round(J35*(H35/100),2) -> 0.12 | L35: =VLOOKUP(A35,KenPom!33:1032,6,FALSE) -> 1.5 | M35: =VLOOKUP(A35,Yahoo!33:1032,6,FALSE) -> 0.62 | N35: =L35-M35 -> 0.88 | O35: =round(N35*(L35/100),2) -> 0.01 | P35: =VLOOKUP(A35,KenPom!33:1032,7,FALSE) -> 0.5 | Q35: =VLOOKUP(A35,Yahoo!33:1032,7,FALSE) -> 0.29 | R35: =P35-Q35 -> 0.21 | S35: =round(R35*(P35/100),2) -> 0 | T35: =VLOOKUP(A35,KenPom!33:1032,8,FALSE) -> 0.08 | U35: =VLOOKUP(A35,Yahoo!33:1032,8,FALSE) -> 0.12 | V35: =T35-U35 -> -0.04 | W35: =round(V35*(T35/100),2) -> 0 | X35: =VLOOKUP(A35,KenPom!33:1032,9,FALSE) -> 0.01 | Y35: =VLOOKUP(A35,Yahoo!33:1032,9,FALSE) -> 0.06 | Z35: =X35-Y35 -> -0.05 | AA35: =round(Z35*(X35/100),2) -> 0
A36: Utah State | B36: 9 | C36: West | D36: =VLOOKUP(A36,KenPom!34:1033,4,FALSE) -> 52.3 | E36: =VLOOKUP(A36,Yahoo!34:1033,4,FALSE) -> 40.59 | F36: =D36-E36 -> 11.71 | G36: =Round(F36*(D36/100),2) -> 6.12 | H36: =VLOOKUP(A36,KenPom!34:1033,5,FALSE) -> 7.5 | I36: =VLOOKUP(A36,Yahoo!34:1033,5,FALSE) -> 1.73 | J36: =H36-I36 -> 5.77 | K36: =round(J36*(H36/100),2) -> 0.43 | L36: =VLOOKUP(A36,KenPom!34:1033,6,FALSE) -> 3.1 | M36: =VLOOKUP(A36,Yahoo!34:1033,6,FALSE) -> 0.67 | N36: =L36-M36 -> 2.43 | O36: =round(N36*(L36/100),2) -> 0.08 | P36: =VLOOKUP(A36,KenPom!34:1033,7,FALSE) -> 1 | Q36: =VLOOKUP(A36,Yahoo!34:1033,7,FALSE) -> 0.26 | R36: =P36-Q36 -> 0.74 | S36: =round(R36*(P36/100),2) -> 0.01 | T36: =VLOOKUP(A36,KenPom!34:1033,8,FALSE) -> 0.3 | U36: =VLOOKUP(A36,Yahoo!34:1033,8,FALSE) -> 0.12 | V36: =T36-U36 -> 0.18 | W36: =round(V36*(T36/100),2) -> 0 | X36: =VLOOKUP(A36,KenPom!34:1033,9,FALSE) -> 0.06 | Y36: =VLOOKUP(A36,Yahoo!34:1033,9,FALSE) -> 0.06 | Z36: =X36-Y36 -> 0 | AA36: =round(Z36*(X36/100),2) -> 0
A37: Saint Louis | B37: 9 | C37: Midwest | D37: =VLOOKUP(A37,KenPom!35:1034,4,FALSE) -> 44 | E37: =VLOOKUP(A37,Yahoo!35:1034,4,FALSE) -> 40.57 | F37: =D37-E37 -> 3.43 | G37: =Round(F37*(D37/100),2) -> 1.51 | H37: =VLOOKUP(A37,KenPom!35:1034,5,FALSE) -> 4.5 | I37: =VLOOKUP(A37,Yahoo!35:1034,5,FALSE) -> 2.19 | J37: =H37-I37 -> 2.31 | K37: =round(J37*(H37/100),2) -> 0.1 | L37: =VLOOKUP(A37,KenPom!35:1034,6,FALSE) -> 1.6 | M37: =VLOOKUP(A37,Yahoo!35:1034,6,FALSE) -> 0.98 | N37: =L37-M37 -> 0.62 | O37: =round(N37*(L37/100),2) -> 0.01 | P37: =VLOOKUP(A37,KenPom!35:1034,7,FALSE) -> 0.4 | Q37: =VLOOKUP(A37,Yahoo!35:1034,7,FALSE) -> 0.41 | R37: =P37-Q37 -> -0.01 | S37: =round(R37*(P37/100),2) -> 0 | T37: =VLOOKUP(A37,KenPom!35:1034,8,FALSE) -> 0.09 | U37: =VLOOKUP(A37,Yahoo!35:1034,8,FALSE) -> 0.16 | V37: =T37-U37 -> -0.07 | W37: =round(V37*(T37/100),2) -> 0 | X37: =VLOOKUP(A37,KenPom!35:1034,9,FALSE) -> 0.02 | Y37: =VLOOKUP(A37,Yahoo!35:1034,9,FALSE) -> 0.08 | Z37: =X37-Y37 -> -0.06 | AA37: =round(Z37*(X37/100),2) -> 0
A38: Iowa | B38: 9 | C38: South | D38: =VLOOKUP(A38,KenPom!36:1035,4,FALSE) -> 57 | E38: =VLOOKUP(A38,Yahoo!36:1035,4,FALSE) -> 48.94 | F38: =D38-E38 -> 8.06 | G38: =Round(F38*(D38/100),2) -> 4.59 | H38: =VLOOKUP(A38,KenPom!36:1035,5,FALSE) -> 14 | I38: =VLOOKUP(A38,Yahoo!36:1035,5,FALSE) -> 4.86 | J38: =H38-I38 -> 9.14 | K38: =round(J38*(H38/100),2) -> 1.28 | L38: =VLOOKUP(A38,KenPom!36:1035,6,FALSE) -> 5.8 | M38: =VLOOKUP(A38,Yahoo!36:1035,6,FALSE) -> 2.8 | N38: =L38-M38 -> 3 | O38: =round(N38*(L38/100),2) -> 0.17 | P38: =VLOOKUP(A38,KenPom!36:1035,7,FALSE) -> 1.8 | Q38: =VLOOKUP(A38,Yahoo!36:1035,7,FALSE) -> 0.49 | R38: =P38-Q38 -> 1.31 | S38: =round(R38*(P38/100),2) -> 0.02 | T38: =VLOOKUP(A38,KenPom!36:1035,8,FALSE) -> 0.5 | U38: =VLOOKUP(A38,Yahoo!36:1035,8,FALSE) -> 0.18 | V38: =T38-U38 -> 0.32 | W38: =round(V38*(T38/100),2) -> 0 | X38: =VLOOKUP(A38,KenPom!36:1035,9,FALSE) -> 0.1 | Y38: =VLOOKUP(A38,Yahoo!36:1035,9,FALSE) -> 0.09 | Z38: =X38-Y38 -> 0.01 | AA38: =round(Z38*(X38/100),2) -> 0
A39: UCF | B39: 10 | C39: East | D39: =VLOOKUP(A39,KenPom!37:1036,4,FALSE) -> 34.2 | E39: =VLOOKUP(A39,Yahoo!37:1036,4,FALSE) -> 30.52 | F39: =D39-E39 -> 3.68 | G39: =Round(F39*(D39/100),2) -> 1.26 | H39: =VLOOKUP(A39,KenPom!37:1036,5,FALSE) -> 8.4 | I39: =VLOOKUP(A39,Yahoo!37:1036,5,FALSE) -> 2.95 | J39: =H39-I39 -> 5.45 | K39: =round(J39*(H39/100),2) -> 0.46 | L39: =VLOOKUP(A39,KenPom!37:1036,6,FALSE) -> 2.1 | M39: =VLOOKUP(A39,Yahoo!37:1036,6,FALSE) -> 0.8 | N39: =L39-M39 -> 1.3 | O39: =round(N39*(L39/100),2) -> 0.03 | P39: =VLOOKUP(A39,KenPom!37:1036,7,FALSE) -> 0.3 | Q39: =VLOOKUP(A39,Yahoo!37:1036,7,FALSE) -> 0.21 | R39: =P39-Q39 -> 0.09 | S39: =round(R39*(P39/100),2) -> 0 | T39: =VLOOKUP(A39,KenPom!37:1036,8,FALSE) -> 0.03 | U39: =VLOOKUP(A39,Yahoo!37:1036,8,FALSE) -> 0.1 | V39: =T39-U39 -> -0.07 | W39: =round(V39*(T39/100),2) -> 0 | X39: =VLOOKUP(A39,KenPom!37:1036,9,FALSE) -> 0.001 | Y39: =VLOOKUP(A39,Yahoo!37:1036,9,FALSE) -> 0.05 | Z39: =X39-Y39 -> -0.049 | AA39: =round(Z39*(X39/100),2) -> 0
A40: Missouri | B40: 10 | C40: West | D40: =VLOOKUP(A40,KenPom!38:1037,4,FALSE) -> 37.3 | E40: =VLOOKUP(A40,Yahoo!38:1037,4,FALSE) -> 34.14 | F40: =D40-E40 -> 3.16 | G40: =Round(F40*(D40/100),2) -> 1.18 | H40: =VLOOKUP(A40,KenPom!38:1037,5,FALSE) -> 7.3 | I40: =VLOOKUP(A40,Yahoo!38:1037,5,FALSE) -> 4.1 | J40: =H40-I40 -> 3.2 | K40: =round(J40*(H40/100),2) -> 0.23 | L40: =VLOOKUP(A40,KenPom!38:1037,6,FALSE) -> 1.9 | M40: =VLOOKUP(A40,Yahoo!38:1037,6,FALSE) -> 1.1 | N40: =L40-M40 -> 0.8 | O40: =round(N40*(L40/100),2) -> 0.02 | P40: =VLOOKUP(A40,KenPom!38:1037,7,FALSE) -> 0.3 | Q40: =VLOOKUP(A40,Yahoo!38:1037,7,FALSE) -> 0.31 | R40: =P40-Q40 -> -0.01 | S40: =round(R40*(P40/100),2) -> 0 | T40: =VLOOKUP(A40,KenPom!38:1037,8,FALSE) -> 0.05 | U40: =VLOOKUP(A40,Yahoo!38:1037,8,FALSE) -> 0.13 | V40: =T40-U40 -> -0.08 | W40: =round(V40*(T40/100),2) -> 0 | X40: =VLOOKUP(A40,KenPom!38:1037,9,FALSE) -> 0.003 | Y40: =VLOOKUP(A40,Yahoo!38:1037,9,FALSE) -> 0.07 | Z40: =X40-Y40 -> -0.067 | AA40: =round(Z40*(X40/100),2) -> 0
...

Sheet KenPom
A1: Kenpom Link: | B1: https://kenpom.substack.com/p/the-2026-ncaa-tournament-odds
A2: Team | B2: Seed | C2: Region | D2: Rd 2 | E2: Sweet 16 | F2: Elite 8 | G2: Final 4 | H2: Final | I2: Champ
A3: Duke | B3: 1 | C3: East | D3: 99.1 | E3: 85.3 | F3: 69 | G3: 52.7 | H3: 33.3 | I3: 21
A4: Arizona | B4: 1 | C4: West | D4: 99.6 | E4: 85.7 | F4: 68.8 | G4: 49.7 | H4: 32.1 | I4: 18.5
A5: Michigan | B5: 1 | C5: Midwest | D5: 99.5 | E5: 88.2 | F5: 70.9 | G5: 50.2 | H5: 30.4 | I5: 18.4
A6: Florida | B6: 1 | C6: South | D6: 99.8 | E6: 77.9 | F6: 53.2 | G6: 30.1 | H6: 15.8 | I6: 7.5
A7: Uconn | B7: 2 | C7: East | D7: 95.9 | E7: 66.1 | F7: 35.5 | G7: 13.1 | H7: 4.9 | I7: 1.9
A8: Purdue | B8: 2 | C8: West | D8: 97.6 | E8: 74.9 | F8: 46.7 | G8: 20.8 | H8: 10.3 | I8: 4.3
A9: Iowa State | B9: 2 | C9: Midwest | D9: 98.4 | E9: 75.3 | F9: 49.4 | G9: 22.9 | H9: 11.2 | I9: 5.4
A10: Houston | B10: 2 | C10: South | D10: 96.9 | E10: 73.5 | F10: 43.6 | G10: 25.1 | H10: 12.9 | I10: 6.1
A11: Michigan State | B11: 3 | C11: East | D11: 91.6 | E11: 57.5 | F11: 32.9 | G11: 12 | H11: 4.6 | I11: 1.8
A12: Gonzaga | B12: 3 | C12: West | D12: 96.3 | E12: 63.4 | F12: 31.6 | G12: 11.7 | H12: 4.9 | I12: 1.7
A13: Virginia | B13: 3 | C13: Midwest | D13: 93.1 | E13: 53.1 | F13: 23.2 | G13: 7.8 | H13: 2.7 | I13: 1
A14: Illinois | B14: 3 | C14: South | D14: 97 | E14: 75.5 | F14: 40.8 | G14: 22.3 | H14: 10.7 | I14: 4.6
... A66: PV/LEH | B66: 16 | C66: South | D66: 0.09 | E66: 0.004 | F66: 0.0001 | G66: 0.0001 | H66: 0.0001 | I66: 0.0001

Sheet Yahoo
A1: Yahoo Link: | B1: https://tournament.fantasysports.yahoo.com/mens-basketball-bracket/pickdistribution
A2: Team | B2: Seed | C2: Region | D2: Rd 2 | E2: Sweet 16 | F2: Elite 8 | G2: Final 4 | H2: Final | I2: Champ
A3: Duke | B3: 1 | C3: East | D3: 98.21 | E3: 93.59 | F3: 78.77 | G3: 64.67 | H3: 49.51 | I3: 30.24
A4: Arizona | B4: 1 | C4: West | D4: 94.82 | E4: 89.38 | F4: 74.48 | G4: 56.08 | H4: 38.93 | I4: 19.37
A5: Michigan | B5: 1 | C5: Midwest | D5: 94.22 | E5: 89.6 | F5: 77.11 | G5: 58.91 | H5: 28.46 | I5: 14.48
A6: Florida | B6: 1 | C6: South | D6: 95.36 | E6: 88.13 | F6: 74.68 | G6: 41.77 | H6: 13.68 | I6: 6.48
A7: Uconn | B7: 2 | C7: East | D7: 96.15 | E7: 77.4 | F7: 48.29 | G7: 13.25 | H7: 7.19 | I7: 3.61
A8: Purdue | B8: 2 | C8: West | D8: 93.62 | E8: 76.5 | F8: 47.5 | G8: 15.85 | H8: 7.47 | I8: 3.17
A9: Iowa State | B9: 2 | C9: Midwest | D9: 91.25 | E9: 69.43 | F9: 47.35 | G9: 16.41 | H9: 5.12 | I9: 1.82
A10: Houston | B10: 2 | C10: South | D10: 93.67 | E10: 81.46 | F10: 58.94 | G10: 34 | H10: 12.62 | I10: 5.2
A11: Michigan State | B11: 3 | C11: East | D11: 94.58 | E11: 73.1 | F11: 34.57 | G11: 7.72 | H11: 3.36 | I11: 1.36
A12: Gonzaga | B12: 3 | C12: West | D12: 91.65 | E12: 64.19 | F12: 30.43 | G12: 10.08 | H12: 4.9 | I12: 1.91
A13: Virginia | B13: 3 | C13: Midwest | D13: 90.14 | E13: 59.96 | F13: 25.79 | G13: 7.57 | H13: 2.39 | I13: 0.77
A14: Illinois | B14: 3 | C14: South | D14: 90.7 | E14: 60.96 | F14: 20.39 | G14: 9.17 | H14: 3.05 | I14: 1.14
... A66: PV/LEH | B66: 16 | C66: South | D66: 1.38 | E66: 0.61 | F66: 0.33 | G66: 0.19 | H66: 0.08 | I66: 0.03

Sheet Leverage Model Long Format
A1: Team | B1: Seed | C1: Region | D1: Round | E1: Win % | F1: Pick % | G1: Leverage | H1: Effective Leverage
A2: Duke | B2: 1 | C2: East | D2: Round of 32 | E2: 99.1 | F2: 98.21 | G2: 0.89 | H2: 0.88
A3: Duke | B3: 1 | C3: East | D3: Sweet 16 | E3: 85.3 | F3: 93.59 | G3: -8.29 | H3: -7.07
A4: Duke | B4: 1 | C4: East | D4: Elite 8 | E4: 69 | F4: 78.77 | G4: -9.77 | H4: -6.74
A5: Duke | B5: 1 | C5: East | D5: Final 4 | E5: 52.7 | F5: 64.67 | G5: -11.97 | H5: -6.31
A6: Duke | B6: 1 | C6: East | D6: Finals | E6: 33.3 | F6: 49.51 | G6: -16.21 | H6: -5.4
A7: Duke | B7: 1 | C7: East | D7: Champion | E7: 21 | F7: 30.24 | G7: -9.24 | H7: -1.94
A8: Arizona | B8: 1 | C8: West | D8: Round of 32 | E8: 99.6 | F8: 94.82 | G8: 4.78 | H8: 4.76
A9: Arizona | B9: 1 | C9: West | D9: Sweet 16 | E9: 85.7 | F9: 89.38 | G9: -3.68 | H9: -3.15
A10: Arizona | B10: 1 | C10: West | D10: Elite 8 | E10: 68.8 | F10: 74.48 | G10: -5.68 | H10: -3.91
A11: Arizona | B11: 1 | C11: West | D11: Final 4 | E11: 49.7 | F11: 56.08 | G11: -6.38 | H11: -3.17
A12: Arizona | B12: 1 | C12: West | D12: Finals | E12: 32.1 | F12: 38.93 | G12: -6.83 | H12: -2.19
A13: Arizona | B13: 1 | C13: West | D13: Champion | E13: 18.5 | F13: 19.37 | G13: -0.87 | H13: -0.16
... A385: PV/LEH | B385: 16 | C385: South | D385: Champion | E385: 0.0001 | F385: 0.03 | G385: -0.0299 | H385: 0
